2022-02-02 10:42:33,083 - (1292, "Truncated incorrect DOUBLE value: 'biology'") 
 
Traceback (most recent call last):
  File "D:\bridgelabz\python\py_mysql\SQL\sql_operations.py", line 28, in delete_query_operation
    if self.cursor_obj.execute(query, data):
  File "C:\Users\vishwanath\AppData\Local\Programs\Python\Python38\lib\site-packages\pymysql\cursors.py", line 148, in execute
    result = self._query(query)
  File "C:\Users\vishwanath\AppData\Local\Programs\Python\Python38\lib\site-packages\pymysql\cursors.py", line 310, in _query
    conn.query(q)
  File "C:\Users\vishwanath\AppData\Local\Programs\Python\Python38\lib\site-packages\pymysql\connections.py", line 548, in query
    self._affected_rows = self._read_query_result(unbuffered=unbuffered)
  File "C:\Users\vishwanath\AppData\Local\Programs\Python\Python38\lib\site-packages\pymysql\connections.py", line 775, in _read_query_result
    result.read()
  File "C:\Users\vishwanath\AppData\Local\Programs\Python\Python38\lib\site-packages\pymysql\connections.py", line 1156, in read
    first_packet = self.connection._read_packet()
  File "C:\Users\vishwanath\AppData\Local\Programs\Python\Python38\lib\site-packages\pymysql\connections.py", line 725, in _read_packet
    packet.raise_for_error()
  File "C:\Users\vishwanath\AppData\Local\Programs\Python\Python38\lib\site-packages\pymysql\protocol.py", line 221, in raise_for_error
    err.raise_mysql_exception(self._data)
  File "C:\Users\vishwanath\AppData\Local\Programs\Python\Python38\lib\site-packages\pymysql\err.py", line 143, in raise_mysql_exception
    raise errorclass(errno, errval)
pymysql.err.OperationalError: (1292, "Truncated incorrect DOUBLE value: 'biology'")
2022-02-02 10:43:09,908 - (1292, "Truncated incorrect DOUBLE value: 'biology'") 
 
Traceback (most recent call last):
  File "D:\bridgelabz\python\py_mysql\SQL\sql_operations.py", line 28, in delete_query_operation
    if self.cursor_obj.execute(query, data):
  File "C:\Users\vishwanath\AppData\Local\Programs\Python\Python38\lib\site-packages\pymysql\cursors.py", line 148, in execute
    result = self._query(query)
  File "C:\Users\vishwanath\AppData\Local\Programs\Python\Python38\lib\site-packages\pymysql\cursors.py", line 310, in _query
    conn.query(q)
  File "C:\Users\vishwanath\AppData\Local\Programs\Python\Python38\lib\site-packages\pymysql\connections.py", line 548, in query
    self._affected_rows = self._read_query_result(unbuffered=unbuffered)
  File "C:\Users\vishwanath\AppData\Local\Programs\Python\Python38\lib\site-packages\pymysql\connections.py", line 775, in _read_query_result
    result.read()
  File "C:\Users\vishwanath\AppData\Local\Programs\Python\Python38\lib\site-packages\pymysql\connections.py", line 1156, in read
    first_packet = self.connection._read_packet()
  File "C:\Users\vishwanath\AppData\Local\Programs\Python\Python38\lib\site-packages\pymysql\connections.py", line 725, in _read_packet
    packet.raise_for_error()
  File "C:\Users\vishwanath\AppData\Local\Programs\Python\Python38\lib\site-packages\pymysql\protocol.py", line 221, in raise_for_error
    err.raise_mysql_exception(self._data)
  File "C:\Users\vishwanath\AppData\Local\Programs\Python\Python38\lib\site-packages\pymysql\err.py", line 143, in raise_mysql_exception
    raise errorclass(errno, errval)
pymysql.err.OperationalError: (1292, "Truncated incorrect DOUBLE value: 'biology'")
2022-02-02 10:50:26,302 - (1292, "Truncated incorrect DOUBLE value: 'biology'") 
 
Traceback (most recent call last):
  File "D:\bridgelabz\python\py_mysql\SQL\sql_operations.py", line 28, in delete_query_operation
    if self.cursor_obj.execute(query, data):
  File "C:\Users\vishwanath\AppData\Local\Programs\Python\Python38\lib\site-packages\pymysql\cursors.py", line 148, in execute
    result = self._query(query)
  File "C:\Users\vishwanath\AppData\Local\Programs\Python\Python38\lib\site-packages\pymysql\cursors.py", line 310, in _query
    conn.query(q)
  File "C:\Users\vishwanath\AppData\Local\Programs\Python\Python38\lib\site-packages\pymysql\connections.py", line 548, in query
    self._affected_rows = self._read_query_result(unbuffered=unbuffered)
  File "C:\Users\vishwanath\AppData\Local\Programs\Python\Python38\lib\site-packages\pymysql\connections.py", line 775, in _read_query_result
    result.read()
  File "C:\Users\vishwanath\AppData\Local\Programs\Python\Python38\lib\site-packages\pymysql\connections.py", line 1156, in read
    first_packet = self.connection._read_packet()
  File "C:\Users\vishwanath\AppData\Local\Programs\Python\Python38\lib\site-packages\pymysql\connections.py", line 725, in _read_packet
    packet.raise_for_error()
  File "C:\Users\vishwanath\AppData\Local\Programs\Python\Python38\lib\site-packages\pymysql\protocol.py", line 221, in raise_for_error
    err.raise_mysql_exception(self._data)
  File "C:\Users\vishwanath\AppData\Local\Programs\Python\Python38\lib\site-packages\pymysql\err.py", line 143, in raise_mysql_exception
    raise errorclass(errno, errval)
pymysql.err.OperationalError: (1292, "Truncated incorrect DOUBLE value: 'biology'")
